[{"id":1053407556,"node_id":"R_kgDOPsm5RA","name":"Django-faille-CVE-2025-57833_test","full_name":"loic-houchi/Django-faille-CVE-2025-57833_test","private":false,"owner":{"login":"loic-houchi","id":194474185,"node_id":"U_kgDOC5dwyQ","avatar_url":"https://avatars.githubusercontent.com/u/194474185?v=4","url":"https://api.github.com/users/loic-houchi","html_url":"https://github.com/loic-houchi","type":"User","site_admin":false},"html_url":"https://github.com/loic-houchi/Django-faille-CVE-2025-57833_test","description":"","fork":false,"url":"https://api.github.com/repos/loic-houchi/Django-faille-CVE-2025-57833_test","created_at":"2025-09-09T12:08:05Z","updated_at":"2025-09-10T06:47:44Z","pushed_at":"2025-09-09T12:09:29Z","stargazers_count":2,"watchers_count":2,"forks_count":0,"archived":false,"disabled":false,"allow_forking":true,"is_template":false,"topics":[],"visibility":"public","forks":0,"watchers":2,"default_branch":"main","score":1}]